Workbook

Sheet Daily Sales
B1: PERIODE OF June 2026 | C1: =CHOOSE(WEEKDAY(DATE(2026,6,1)+COLUMN()-2.1),"sunday","monday","tuesday","wednesday","thursday","friday","saturday") -> monday | D1: =CHOOSE(WEEKDAY(DATE(2026,6,1)+COLUMN()-2.1),"sunday","monday","tuesday","wednesday","thursday","friday","saturday") -> tuesday | E1: =CHOOSE(WEEKDAY(DATE(2026,6,1)+COLUMN()-2.1),"sunday","monday","tuesday","wednesday","thursday","friday","saturday") -> wednesday | F1: =CHOOSE(WEEKDAY(DATE(2026,6,1)+COLUMN()-2.1),"sunday","monday","tuesday","wednesday","thursday","friday","saturday") -> thursday | G1: =CHOOSE(WEEKDAY(DATE(2026,6,1)+COLUMN()-2.1),"sunday","monday","tuesday","wednesday","thursday","friday","saturday") -> friday | H1: =CHOOSE(WEEKDAY(DATE(2026,6,1)+COLUMN()-2.1),"sunday","monday","tuesday","wednesday","thursday","friday","saturday") -> saturday | I1: =CHOOSE(WEEKDAY(DATE(2026,6,1)+COLUMN()-2.1),"sunday","monday","tuesday","wednesday","thursday","friday","saturday") -> sunday | J1: =CHOOSE(WEEKDAY(DATE(2026,6,1)+COLUMN()-2.1),"sunday","monday","tuesday","wednesday","thursday","friday","saturday") -> monday | ... AF1: =CHOOSE(WEEKDAY(DATE(2026,6,1)+COLUMN()-2.1),"sunday","monday","tuesday","wednesday","thursday","friday","saturday") -> tuesday
B2: DESCRIPTION | C2: 46174 | D2: 46175 | E2: 46176 | F2: 46177 | G2: 46178 | H2: 46179 | I2: 46180 | J2: 46181 | K2: 46182 | L2: 46183 | M2: 46184 | N2: 46185 | O2: 46186 | P2: 46187 | Q2: 46188 | R2: 46189 | S2: 46190 | T2: 46191 | U2: 46192 | V2: 46193 | W2: 46194 | X2: 46195 | Y2: 46196 | Z2: 46197 | AA2: 46198 | AB2: 46199 | AC2: 46200 | AD2: 46201 | AE2: 46202 | AF2: 46203 | AG2: TOTAL
B3: Terrace Revenue: | AG3: =SUM(C3:AF3) -> 0
A4: 4-2100 | B4: Sales Food TERRACE | C4: 4945000 | D4: =3035000+250000+305000 -> 3590000 | E4: 4209000 | F4: 3432500 | G4: 8275000 | H4: 5030000 | I4: 5040000 | J4: 3341000 | K4: 4035000 | L4: 6649000 | M4: 5400000 | N4: =9149000+125000 -> 9274000 | O4: =5485000 -> 5485000 | P4: 5760000 | Q4: 4420000 | R4: 7796750 | S4: 5875875 | T4: =6480000 -> 6480000 | U4: =5535000 -> 5535000 | V4: =6158000 -> 6158000 | W4: =5208000+125000 -> 5333000 | X4: 4850000 | Y4: 5089000 | Z4: =3845000 -> 3845000 | AA4: 4282500 | AB4: 6577500 | AC4: 5328750 | AD4: 3120000 | AE4: 5250000 | AF4: =4598750 -> 4598750 | AG4: =SUM(C4:AF4) -> 159005625
A5: 4-2200 | B5: Sales Beverages TERRACE | C5: 8420000 | D5: =2690000+50000 -> 2740000 | E5: 7993000 | F5: 5855000 | G5: 12875000 | H5: 6765000 | I5: 5610000 | J5: 2674000 | K5: 5815000 | L5: 7545000 | M5: 5150000 | N5: =13090000 -> 13090000 | O5: =10725000 -> 10725000 | P5: 11125000 | Q5: 6690000 | R5: 8883000 | S5: 11605000 | T5: =10075000 -> 10075000 | U5: =11900000 -> 11900000 | V5: =12055000 -> 12055000 | W5: 9126000 | X5: 7930000 | Y5: 8795000 | Z5: =6485000 -> 6485000 | AA5: 6225000 | AB5: =13445000 -> 13445000 | AC5: 10890000 | AD5: 3978000 | AE5: 6645000 | AF5: =7464000 -> 7464000 | AG5: =SUM(C5:AF5) -> 248573000
A6: 4-2400 | B6: Sales Cigarette TERRACE | E6: 259000 | F6: 70000 | G6: 210000 | H6: 140000 | I6: 70000 | J6: 70000 | K6: 70000 | N6: =210000+358000 -> 568000 | O6: =210000 -> 210000 | P6: 420000 | R6: 140000 | S6: 70000 | T6: =140000+358000 -> 498000 | U6: =70000 -> 70000 | V6: =210000 -> 210000 | W6: 280000 | X6: 140000 | Y6: 70000 | Z6: =140000 -> 140000 | AA6: 70000 | AB6: =210000+120000 -> 330000 | AD6: 70000 | AG6: =SUM(C6:AF6) -> 4175000
A7: 4-2300 | B7: Sales Shisa TERRACE | C7: 1500000 | E7: 500000 | G7: 500000 | I7: 250000 | K7: 250000 | O7: =250000 -> 250000 | R7: 250000 | V7: =500000 -> 500000 | Z7: =250000 -> 250000 | AC7: 250000 | AD7: 250000 | AE7: 250000 | AG7: =SUM(C7:AF7) -> 5000000
A8: 4-2602 | B8: Merchandise TERRACE | AG8: =SUM(C8:AF8) -> 0
B9: Total Terrace Revenue | C9: =SUM(C4:C8) -> 14865000 | D9: =SUM(D4:D8) -> 6330000 | E9: =SUM(E4:E8) -> 12961000 | F9: =SUM(F4:F8) -> 9357500 | G9: =SUM(G4:G8) -> 21860000 | H9: =SUM(H4:H8) -> 11935000 | I9: =SUM(I4:I8) -> 10970000 | J9: =SUM(J4:J8) -> 6085000 | ... AG9: =SUM(AG4:AG8) -> 416753625
B10: Spend per Guest | C10: 42 | D10: 23 | E10: 40 | F10: 29 | G10: 61 | H10: 48 | I10: 39 | J10: 23 | K10: 49 | L10: 51 | M10: 40 | N10: 68 | O10: =76 -> 76 | P10: 57 | Q10: 43 | R10: 57 | S10: 50 | T10: =56 -> 56 | U10: =72 -> 72 | V10: 66 | W10: =57 -> 57 | X10: 47 | Y10: 64 | Z10: 45 | AA10: 39 | AB10: 65 | AC10: 61 | AD10: 30 | AE10: 45 | AF10: =40 -> 40 | AG10: =SUM(C10:AF10) -> 1483
B11: Club Revenue: | AG11: =SUM(C11:AF11) -> 0
A12: 4-2200 | B12: Sales Beverages CLUB | C12: 12575000 | D12: 27335000 | E12: 12240000 | F12: =32025000+1725000 -> 33750000 | G12: =6875000+53315000 -> 60190000 | H12: =27995000+66900000 -> 94895000 | I12: =11220000 -> 11220000 | J12: 48200000 | K12: =38654000 -> 38654000 | L12: 30350000 | M12: =3230000+19905000 -> 23135000 | N12: =30405000+2835000 -> 33240000 | O12: =54365000+16860000 -> 71225000 | P12: =9165000+20000 -> 9185000 | Q12: 13455000 | R12: 35500000 | S12: 27260000 | T12: =1420000+14465000 -> 15885000 | U12: 47900000 | V12: =65320000+20010000 -> 85330000 | W12: 13450000 | X12: =450000+12095000 -> 12545000 | Y12: =27903000 -> 27903000 | Z12: 21060000 | AA12: =23050000+1365000 -> 24415000 | AB12: =55390000 -> 55390000 | AC12: =59160000+19995000 -> 79155000 | AD12: 15955000 | AE12: =204000+25845000 -> 26049000 | AF12: =16715000+466752 -> 17181752 | AG12: =SUM(C12:AF12) -> 1024627752
A13: 4-2400 | B13: Sales Cigarette CLUB | D13: =700000+120000 -> 820000 | E13: 420000 | F13: 490000 | G13: =70000+1190000 -> 1260000 | H13: =770000+770000 -> 1540000 | I13: =630000 -> 630000 | J13: 630000 | K13: =840000 -> 840000 | L13: 70000 | M13: =560000 -> 560000 | N13: =1050000 -> 1050000 | O13: =910000+770000 -> 1680000 | P13: 140000 | Q13: 70000 | R13: 560000 | S13: 700000 | T13: =560000 -> 560000 | U13: 770000 | V13: =910000+280000 -> 1190000 | W13: 210000 | Y13: =140000 -> 140000 | Z13: 350000 | AA13: 840000 | AB13: =1330000 -> 1330000 | AC13: =1820000+1260000 -> 3080000 | AE13: =700000 -> 700000 | AF13: 490000 | AG13: =SUM(C13:AF13) -> 21120000
A14: 4-2100 | B14: Sales Food CLUB | C14: 100000 | D14: 350000 | E14: 530000 | F14: =600000+190000 -> 790000 | G14: 1160000 | H14: =500000+990000 -> 1490000 | I14: =245000 -> 245000 | J14: 1040000 | K14: =250000 -> 250000 | M14: =150000+150000 -> 300000 | N14: =1170000 -> 1170000 | O14: =1090000+150000 -> 1240000 | P14: 100000 | Q14: 100000 | R14: 390000 | S14: 100000 | T14: =650000+490000 -> 1140000 | U14: 570000 | V14: =1815000+140000 -> 1955000 | W14: 200000 | X14: =250000 -> 250000 | Y14: =1020000 -> 1020000 | Z14: 690000 | AA14: =280000+100000 -> 380000 | AB14: =600000 -> 600000 | AC14: =1430000+375000 -> 1805000 | AD14: 100000 | AE14: =450000 -> 450000 | AF14: 450000 | AG14: =SUM(C14:AF14) -> 18965000
A15: 4-2300 | B15: Sales Shisa CLUB | D15: 250000 | E15: 750000 | F15: 750000 | G15: 1750000 | H15: =750000 -> 750000 | J15: 500000 | K15: =250000 -> 250000 | N15: =750000 -> 750000 | O15: =500000 -> 500000 | P15: 250000 | Q15: 120000 | R15: 250000 | T15: =250000 -> 250000 | U15: 500000 | V15: 1200000 | AB15: =250000 -> 250000 | AC15: =500000 -> 500000 | AF15: 500000 | AG15: =SUM(C15:AF15) -> 10070000
A16: 4-2601 | B16: Red Room | AG16: =SUM(C16:AF16) -> 0
A17: 4-2601 | B17: Misc | E17: =200000 -> 200000 | G17: 120000 | Z17: 2500000 | AF17: =45000000 -> 45000000 | AG17: =SUM(C17:AF17) -> 47820000
A18: 4-2602 | B18: Merchandise | AG18: =SUM(C18:AF18) -> 0
A19: 4-2500 | B19: Sales Ticket | C19: 12404452 | D19: 6627036 | E19: 13763844 | F19: =12404452+1656759 -> 14061211 | G19: 24936347 | H19: 36321255 | I19: 11214984 | J19: 13593920 | K19: =11639794 -> 11639794 | L19: 10195440 | M19: =1444354+12404452 -> 13848806 | N19: =17842020 -> 17842020 | O19: =31520902 -> 31520902 | P19: 9855592 | Q19: 11045060 | R19: 11384908 | S19: =10705212+200000 -> 10905212 | T19: =1444354+9345820 -> 10790174 | U19: 22175082 | V19: 28674675 | W19: 9515744 | X19: 11554832 | Y19: 17842020 | Z19: 9005972 | AA19: =9685668+2039088 -> 11724756 | AB19: =25616043+3000000 -> 28616043 | AC19: =25913410 -> 25913410 | AD19: 9005972 | AE19: 9685668 | AF19: 11045060 | AG19: =SUM(C19:AF19) -> 466710191
B20: Total Club Revenue | C20: =SUM(C12:C19) -> 25079452 | D20: =SUM(D12:D19) -> 35382036 | E20: =SUM(E12:E19) -> 27903844 | F20: =SUM(F12:F19) -> 49841211 | G20: =SUM(G12:G19) -> 89416347 | H20: =SUM(H12:H19) -> 134996255 | I20: =SUM(I12:I19) -> 23309984 | J20: =SUM(J12:J19) -> 63963920 | ... AG20: =SUM(AG12:AG19) -> 1589312943
B21: Spend per Guest | C21: 51 | D21: 76 | E21: 73 | F21: =113+13 -> 126 | G21: =40+123 -> 163 | H21: =75+113 -> 188 | I21: 63 | J21: 95 | K21: =103 -> 103 | L21: 51 | M21: =5+80 -> 85 | N21: =70 -> 70 | O21: =128+62 -> 190 | P21: 30 | Q21: 54 | R21: 92 | S21: 68 | T21: =9+60 -> 69 | U21: =151 -> 151 | V21: =135+67 -> 202 | W21: =68 -> 68 | X21: =70 -> 70 | Y21: =136 -> 136 | Z21: 33 | AA21: 56 | AB21: =177 -> 177 | AC21: =134+70 -> 204 | AD21: 52 | AE21: =52 -> 52 | AF21: =61 -> 61 | AG21: =SUM(C21:AF21) -> 2909
B22: Deduction: | AG22: =SUM(C22:AF22) -> 0
A23: 4-5110 | B23: Discount | C23: =SUM(C24:C26) -> 626500 | D23: =SUM(D24:D26) -> 902500 | E23: =SUM(E24:E26) -> 374000 | F23: =SUM(F24:F26) -> 1759000 | G23: =SUM(G24:G26) -> 1352000 | H23: =SUM(H24:H26) -> 2866000 | I23: =SUM(I24:I26) -> 787000 | J23: =SUM(J24:J26) -> 691500 | ... AG23: =SUM(AG24:AG26) -> 30762000
B24: Disc 10-15% | H24: =250000+260000 -> 510000 | O24: =700000 -> 700000 | R24: =1400000 -> 1400000 | AG24: =SUM(C24:AF24) -> 2610000
B25: Disc 20-30% | C25: 19000 | E25: 54000 | F25: 1034000 | G25: =252000+750000 -> 1002000 | H25: =66000 -> 66000 | I25: =12000+35000 -> 47000 | J25: =514000 -> 514000 | M25: =17000 -> 17000 | N25: =750000+90000+36000 -> 876000 | O25: =650000+195000 -> 845000 | P25: =24000+24000 -> 48000 | Q25: =64000+20000 -> 84000 | R25: 64000 | S25: =29000+122000 -> 151000 | T25: =39000+49000 -> 88000 | U25: =129000+58000 -> 187000 | V25: =650000+190000+18000 -> 858000 | W25: =15000+40000 -> 55000 | X25: =48000 -> 48000 | Y25: =10000 -> 10000 | AA25: 26000 | AB25: =750000 -> 750000 | AC25: =30000+650000+43000+20000 -> 743000 | AE25: =135000 -> 135000 | AF25: =58000+203000 -> 261000 | AG25: =SUM(C25:AF25) -> 7982000
B26: Disc 50% | C26: 607500 | D26: 902500 | E26: 320000 | F26: 725000 | G26: =317500+32500 -> 350000 | H26: =442500+1627500+220000 -> 2290000 | I26: =75000+665000 -> 740000 | J26: =25000+152500 -> 177500 | K26: 785000 | L26: 160000 | M26: =362500 -> 362500 | N26: =36000+440000+24000 -> 500000 | O26: =412500+392500+192500 -> 997500 | P26: =137500 -> 137500 | Q26: =302500 -> 302500 | R26: =250000+540000 -> 790000 | S26: =250000 -> 250000 | T26: =302500+50000 -> 352500 | U26: =485000+437500 -> 922500 | V26: =1162500+350000 -> 1512500 | W26: =412500 -> 412500 | X26: =50000+560000 -> 610000 | Y26: =495000+137500 -> 632500 | Z26: =85000+230000 -> 315000 | AA26: =335000 -> 335000 | AB26: =130000 -> 130000 | AC26: =175000+482500+152500 -> 810000 | AD26: =340000+1195000 -> 1535000 | AE26: =1625000+15000 -> 1640000 | AF26: =497500+67500 -> 565000 | AG26: =SUM(C26:AF26) -> 20170000
C27: =C9+C20-C23 -> 39317952 | D27: =D9+D20-D23 -> 40809536 | E27: =E9+E20-E23 -> 40490844 | F27: =F9+F20-F23 -> 57439711 | G27: =G9+G20-G23 -> 109924347 | H27: =H9+H20-H23 -> 144065255 | I27: =I9+I20-I23 -> 33492984 | J27: =J9+J20-J23 -> 69357420 | ... AG27: =AG9+AG20-AG23 -> 1975304568
A28: 2-2106 | B28: Service Charges 7% | C28: =C27*7% -> 2752256.6 | D28: =D27*7% -> 2856667.5 | E28: 2820359.1 | F28: =F27*7% -> 4020779.8 | G28: =G27*7% -> 7694704.3 | H28: =H27*7% -> 10084568 | I28: =I27*7% -> 2344508.9 | J28: =J27*7% -> 4855019.4 | K28: =K27*7% -> 4271315.6 | L28: =L27*7% -> 3825460.8 | M28: =M27*7% -> 3361001.4 | ... Q28: =Q27*7% -> 2485949.2 | R28: 4360364 | S28: 3818095 | T28: =T27*7% -> 3166637.2 | U28: =U27*7% -> 6181740.7 | V28: =V27*7% -> 9443152.2 | W28: =W27*7% -> 2635307.1 | X28: =X27*7% -> 2562828.2 | Y28: =Y27*7% -> 4215156.4 | Z28: 2905768 | AA28: =AA27*7% -> 3330337.9 | AB28: 7186098 | AC28: =AC27*7% -> 8775841.2 | AD28: =AD27*7% -> 2166078 | AE28: =AE27*7%-14280 -> 3293546.8 | AF28: 2830576.7 | AG28: =SUM(C28:AF28) -> 1.3452272e+08
A29: 2-3101 | B29: Tax PB1 10% | C29: =SUM(C27:C28)*10% -> 4207020.9 | D29: =SUM(D27:D28)*10% -> 4366620.4 | E29: 4311120.3 | F29: =SUM(F27:F28)*10% -> 6146049.1 | G29: =SUM(G27:G28)*10% -> 11761905 | H29: =SUM(H27:H28)*10% -> 15414982 | I29: =SUM(I27:I28)*10% -> 3583749.3 | J29: =SUM(J27:J28)*10% -> 7421243.9 | K29: =SUM(K27:K28)*10% -> 6529011 | L29: =SUM(L27:L28)*10% -> 5847490.1 | M29: =SUM(M27:M28)*10% -> 5137530.7 | ... Q29: =SUM(Q27:Q28)*10% -> 3799950.9 | R29: 6665127 | S29: 5836232 | T29: =SUM(T27:T28)*10% -> 4840431.1 | U29: =SUM(U27:U28)*10% -> 9449232.3 | V29: =SUM(V27:V28)*10% -> 14434533 | W29: =SUM(W27:W28)*10% -> 4028255.1 | X29: =SUM(X27:X28)*10% -> 3917466 | Y29: =SUM(Y27:Y28)*10% -> 6443167.6 | Z29: 4441674 | AA29: =SUM(AA27:AA28)*10% -> 5090659.4 | AB29: 10984464 | AC29: =SUM(AC27:AC28)*10% -> 13414500 | AD29: =SUM(AD27:AD28)*10% -> 3311005 | AE29: =SUM(AE27:AE28)*10%-20400 -> 5034421.5 | AF29: 4326738.7 | AG29: =SUM(C29:AF29) -> 2.0562759e+08
B30: Total All Income | C30: =C27+C28+C29 -> 46277230 | D30: =D27+D28+D29 -> 48032824 | E30: =E27+E28+E29 -> 47622323 | F30: =F27+F28+F29 -> 67606540 | G30: =G27+G28+G29 -> 1.2938096e+08 | H30: =H27+H28+H29 -> 1.6956481e+08 | I30: =I27+I28+I29 -> 39421242 | J30: =J27+J28+J29 -> 81633683 | ... AG30: =AG27+AG28+AG29 -> 2.3154549e+09
AG31: =SUM(C31:AF31) -> 0
A32: 1-1119 | B32: Cash IDR | C32: =6002700+4500000 -> 10502700 | D32: 7081180 | E32: 9760327 | F32: 6021430 | G32: =818015+6900080+4825700+3808495 -> 16352290 | H32: =1700765+941600+9250117+6755980 -> 18648462 | I32: =1863191+4600036+294250 -> 6757477 | J32: =1821408+712085+3800043 -> 6333536 | K32: =641465+3100038+3174958 -> 6916461 | L32: =3800033+900405+3819365 -> 8519803 | M32: =597175+4600040+394295+1930280 -> 7521790 | N32: =2450057+2053285+523765+3800533 -> 8827640 | O32: =5965504+1047530+9350102+4684280 -> 21047416 | P32: =4835975+595562+2600031 -> 8031568 | Q32: =47080+5049331+2400060 -> 7496471 | R32: =4600037+788545+5034280 -> 10422862 | S32: =3200035+4631495+1400180 -> 9231710 | T32: =700005+4800030+6638280+847440 -> 12985755 | U32: =5237605+973725+5500072 -> 11711402 | V32: =2191470+682660+4596185+8750092 -> 16220407 | W32: =2200031+323675+2542320 -> 5066026 | X32: =1600037+388410+6979610 -> 8968057 | Y32: =2365770+894520+5200057 -> 8460347 | Z32: =2698273+3800029+4599128 -> 11097430 | AA32: =3595735+6860560+3200032+550006 -> 14206333 | AB32: =5000083+5371413+6020355 -> 16391851 | AC32: =3931180+622425+6250084+617925 -> 11421614 | AD32: =1324125+3600029+300135 -> 5224289 | AE32: =459030+5720220+3400032 -> 9579282 | AF32: =5049330+2377540+3800035 -> 11226905 | AG32: =SUM(C32:AF32) -> 312032821 | AH32: =SUM(AG32:AG45)+AG48+AG49 -> 2300913831 | AI32: total
A33: 1-1217 | B33: Bank transfer | H33: =1000000+7000000 -> 8000000 | O33: =6997490 -> 6997490 | V33: =3000000 -> 3000000 | AB33: =2967390 -> 2967390 | AE33: =204000 -> 204000 | AF33: =45000000 -> 45000000 | AG33: =SUM(C33:AF33) -> 66168880
B34: Credit Cards: | AG34: =SUM(C34:AF34) -> 0
A35: 1-1216 | B35: Cim Niaga TBB | G35: =1000450 -> 1000450 | H35: 23967805 | K35: 4731541 | L35: 0 | N35: =5117700 -> 5117700 | O35: =7431474 -> 7431474 | P35: =5296500 -> 5296500 | Q35: =117700 -> 117700 | U35: =9273410 -> 9273410 | V35: =14008585 -> 14008585 | AA35: =3848790 -> 3848790 | AB35: =4265320 -> 4265320 | AC35: =1553640 -> 1553640 | AG35: =SUM(C35:AF35) -> 80612915 | AH35: =AG35 -> 80612915 | AI35: cimb
A36: 1-1213 | B36: Mandiri Debet | C36: 258490 | D36: 0 | E36: 515526 | F36: 4896050 | G36: =2315185 -> 2315185 | H36: 1000000 | I36: =200000 -> 200000 | J36: 623810 | K36: 2244878 | L36: =200000 -> 200000 | M36: 3295600 | N36: =250000 -> 250000 | O36: =947260 -> 947260 | P36: =658850 -> 658850 | Q36: =0 -> 0 | R36: =41195 -> 41195 | S36: =200000 -> 200000 | T36: =600000 -> 600000 | U36: =644933 -> 644933 | V36: =0 -> 0 | W36: =188320 -> 188320 | X36: =3260290 -> 3260290 | Y36: =70620 -> 70620 | Z36: 788320 | AA36: =0 -> 0 | AB36: =7992220 -> 7992220 | AC36: =5950090 -> 5950090 | AD36: =1259390 -> 1259390 | AE36: =182435 -> 182435 | AF36: =4319500 -> 4319500 | AG36: =SUM(C36:AF36) -> 42902962
A37: 1-1213 | B37: Mandiri CC | C37: 24448395 | D37: 23991345 | E37: 24441385 | F37: 34067990 | G37: =70510841 -> 70510841 | H37: 58769985 | I37: =21889110 -> 21889110 | J37: 39201170 | K37: 39943800 | L37: =48217543 -> 48217543 | M37: 27850285 | N37: =42195762 -> 42195762 | O37: =47519425 -> 47519425 | P37: =21388735 -> 21388735 | Q37: =26950969 -> 26950969 | R37: =31067502 -> 31067502 | S37: =43515705 -> 43515705 | T37: =33303956 -> 33303956 | U37: =39179617 -> 39179617 | V37: =51650340 -> 51650340 | W37: =23978930 -> 23978930 | X37: =23665505 -> 23665505 | Y37: =26241603 -> 26241603 | Z37: 22489950 | AA37: =29125110 -> 29125110 | AB37: =47648231 -> 47648231 | AC37: =50239425 -> 50239425 | AD37: =12721030 -> 12721030 | AE37: =14985620 -> 14985620 | AF37: =13302648 -> 13302648 | AG37: =SUM(C37:AF37) -> 1014501912
A38: 1-1213 | B38: Mandiri NPG | C38: 1435490 | D38: 1106380 | E38: 1923855 | F38: 2159255 | G38: =4352295 -> 4352295 | H38: 5641915 | I38: =3330460 -> 3330460 | J38: 694160 | K38: 7755800 | L38: =1547485 -> 1547485 | M38: 3544925 | N38: =5301650 -> 5301650 | O38: =17629570 -> 17629570 | P38: =2025900 -> 2025900 | Q38: =1029515 -> 1029515 | R38: =4496185 -> 4496185 | S38: =4231675 -> 4231675 | T38: =1247620 -> 1247620 | U38: =9220045 -> 9220045 | V38: =13661962 -> 13661962 | W38: =4342860 -> 4342860 | X38: =1553280 -> 1553280 | Y38: =4748475 -> 4748475 | Z38: 5049330 | AA38: =3833268 -> 3833268 | AB38: =6993985 -> 6993985 | AC38: =27384420 -> 27384420 | AD38: =1247350 -> 1247350 | AE38: =16624315 -> 16624315 | AF38: =6260920 -> 6260920 | AG38: =SUM(C38:AF38) -> 170374345
A39: 1-1213 | B39: Mandiri QR | C39: 2350833 | D39: 15065331 | E39: 1947755 | F39: 15820360 | G39: =6931023 -> 6931023 | H39: 20328480 | I39: =4392433 -> 4392433 | J39: 9768560 | K39: 3579576 | L39: =3942590 -> 3942590 | M39: 10374944 | N39: =8631698 -> 8631698 | O39: =20905847 -> 20905847 | P39: =1435670 -> 1435670 | Q39: =4383335 -> 4383335 | R39: =1665365 -> 1665365 | S39: =5494056 -> 5494056 | T39: =3470703 -> 3470703 | U39: =19802615 -> 19802615 | V39: =28701598 -> 28701598 | W39: =8849691 -> 8849691 | X39: =2868169 -> 2868169 | Y39: =23593748 -> 23593748 | Z39: 5621723 | AA39: =4671918 -> 4671918 | AB39: =20505918 -> 20505918 | AC39: =32008437 -> 32008437 | AD39: =9962765 -> 9962765 | AE39: =8409485 -> 8409485 | AF39: =10319943 -> 10319943 | AG39: =SUM(C39:AF39) -> 315804569 | AH39: =SUM(AG36:AG39)+AG49 -> 1543805788 | AI39: mandiri
A40: 1-1217 | B40: BCA CC | C40: 6579340 | D40: 70620 | E40: 7497490 | F40: 1571295 | G40: =11755980 -> 11755980 | H40: 16559213 | I40: =1412400 -> 1412400 | J40: 19067400 | K40: 5267075 | L40: =1218195 -> 1218195 | M40: 2061670 | N40: =14708542 -> 14708542 | O40: =11698030 -> 11698030 | P40: =2100945 -> 2100945 | Q40: =759165 -> 759165 | R40: =2410865 -> 2410865 | S40: =1094610 -> 1094610 | T40: =1259390 -> 1259390 | U40: =7438640 -> 7438640 | V40: =17273825 -> 17273825 | W40: =1014565 -> 1014565 | X40: =2006783 -> 2006783 | Y40: =2241008 -> 2241008 | Z40: 5649600 | AB40: =4849090 -> 4849090 | AC40: =8074220 -> 8074220 | AD40: =1842005 -> 1842005 | AE40: =3330910 -> 3330910 | AF40: =564960 -> 564960 | AG40: =SUM(C40:AF40) -> 161377831
...

Sheet GL
I1: PT TAMAN BINTANG BALI
I2: GENERAL LEDGER
I3: MONTH OF June 2026
H4: =SUBTOTAL(9,H6:H6119) -> 1.0865818e+10 | I4: =SUBTOTAL(9,I6:I6119) -> 1.0865818e+10 | J4: =H4-I4 -> 0.38249969
B5: DATE | C5: REFF# | E5: ACCT NAME | F5: DESCRIPTION | G5: QTY | H5: TRANSACTION IN RP
E6: =TRIM(VLOOKUP(D6,TB!$B$9:$C$1500,2,FALSE)) -> #N/A | J6: =H6-I6 -> 0
A7: =IF(E7="","",MATCH(E7,'Daily Sales'!B$4:B$51,0)+3) -> 4 | B7: 46174 | C7: DS26-0601 | D7: {=IF($A7="","",INDEX('Daily Sales'!A:A,$A7))} -> 4-2100 | E7: Sales Food TERRACE | F7: =E7 -> Sales Food TERRACE | H7: {=IF($A7="","", IF( OR( $A7=23, AND($A7>=32,$A7<=50) ), IFERROR( INDEX('Daily Sales'!$C:$AG, $A7, MATCH(TEXT($B7,"0"),TEXT('Daily Sales'!$C$2:$AG$2,"0"),0) ), ""), "") )} | I7: {=IF($A7="","", IF( OR( AND($A7>=4,$A7<=8), AND($A7>=12,$A7<=19), AND($A7>=28,$A7<=29) ), IFERROR( INDEX('Daily Sales'!$C:$AG, $A7, MATCH(TEXT($B7,"0"),TEXT('Daily Sales'!$C$2:$AG$2,"0"),0) ), ""), "") )} -> 4945000 | J7: =J6+H7-I7 -> #VALUE!
A8: =IF(E8="","",MATCH(E8,'Daily Sales'!B$4:B$51,0)+3) -> 5 | B8: 46174 | C8: DS26-0601 | D8: {=IF($A8="","",INDEX('Daily Sales'!A:A,$A8))} -> 4-2200 | E8: Sales Beverages TERRACE | F8: =E8 -> Sales Beverages TERRACE | H8: {=IF($A8="","", IF( OR( $A8=23, AND($A8>=32,$A8<=50) ), IFERROR( INDEX('Daily Sales'!$C:$AG, $A8, MATCH(TEXT($B8,"0"),TEXT('Daily Sales'!$C$2:$AG$2,"0"),0) ), ""), "") )} | I8: {=IF($A8="","", IF( OR( AND($A8>=4,$A8<=8), AND($A8>=12,$A8<=19), AND($A8>=28,$A8<=29) ), IFERROR( INDEX('Daily Sales'!$C:$AG, $A8, MATCH(TEXT($B8,"0"),TEXT('Daily Sales'!$C$2:$AG$2,"0"),0) ), ""), "") )} -> 8420000 | J8: =J7+H8-I8 -> #VALUE!
A9: =IF(E9="","",MATCH(E9,'Daily Sales'!B$4:B$51,0)+3) -> 6 | B9: 46174 | C9: DS26-0601 | D9: {=IF($A9="","",INDEX('Daily Sales'!A:A,$A9))} -> 4-2400 | E9: Sales Cigarette TERRACE | F9: =E9 -> Sales Cigarette TERRACE | H9: {=IF($A9="","", IF( OR( $A9=23, AND($A9>=32,$A9<=50) ), IFERROR( INDEX('Daily Sales'!$C:$AG, $A9, MATCH(TEXT($B9,"0"),TEXT('Daily Sales'!$C$2:$AG$2,"0"),0) ), ""), "") )} | I9: {=IF($A9="","", IF( OR( AND($A9>=4,$A9<=8), AND($A9>=12,$A9<=19), AND($A9>=28,$A9<=29) ), IFERROR( INDEX('Daily Sales'!$C:$AG, $A9, MATCH(TEXT($B9,"0"),TEXT('Daily Sales'!$C$2:$AG$2,"0"),0) ), ""), "") )} -> 0 | J9: =J8+H9-I9 -> #VALUE!
A10: =IF(E10="","",MATCH(E10,'Daily Sales'!B$4:B$51,0)+3) -> 7 | B10: 46174 | C10: DS26-0601 | D10: {=IF($A10="","",INDEX('Daily Sales'!A:A,$A10))} -> 4-2300 | E10: Sales Shisa TERRACE | F10: =E10 -> Sales Shisa TERRACE | H10: {=IF($A10="","", IF( OR( $A10=23, AND($A10>=32,$A10<=50) ), IFERROR( INDEX('Daily Sales'!$C:$AG, $A10, MATCH(TEXT($B10,"0"),TEXT('Daily Sales'!$C$2:$AG$2,"0"),0) ), ""), "") )} | I10: {=IF($A10="","", IF( OR( AND($A10>=4,$A10<=8), AND($A10>=12,$A10<=19), AND($A10>=28,$A10<=29) ), IFERROR( INDEX('Daily Sales'!$C:$AG, $A10, MATCH(TEXT($B10,"0"),TEXT('Daily Sales'!$C$2:$AG$2,"0"),0) ), ""), "") )} -> 1500000 | J10: =J9+H10-I10 -> #VALUE!
A11: =IF(E11="","",MATCH(E11,'Daily Sales'!B$4:B$51,0)+3) -> 12 | B11: 46174 | C11: DS26-0601 | D11: {=IF($A11="","",INDEX('Daily Sales'!A:A,$A11))} -> 4-2200 | E11: Sales Beverages CLUB | F11: =E11 -> Sales Beverages CLUB | H11: {=IF($A11="","", IF( OR( $A11=23, AND($A11>=32,$A11<=50) ), IFERROR( INDEX('Daily Sales'!$C:$AG, $A11, MATCH(TEXT($B11,"0"),TEXT('Daily Sales'!$C$2:$AG$2,"0"),0) ), ""), "") )} | I11: {=IF($A11="","", IF( OR( AND($A11>=4,$A11<=8), AND($A11>=12,$A11<=19), AND($A11>=28,$A11<=29) ), IFERROR( INDEX('Daily Sales'!$C:$AG, $A11, MATCH(TEXT($B11,"0"),TEXT('Daily Sales'!$C$2:$AG$2,"0"),0) ), ""), "") )} -> 12575000 | J11: =J10+H11-I11 -> #VALUE!
A12: =IF(E12="","",MATCH(E12,'Daily Sales'!B$4:B$51,0)+3) -> 13 | B12: 46174 | C12: DS26-0601 | D12: {=IF($A12="","",INDEX('Daily Sales'!A:A,$A12))} -> 4-2400 | E12: Sales Cigarette CLUB | F12: =E12 -> Sales Cigarette CLUB | H12: {=IF($A12="","", IF( OR( $A12=23, AND($A12>=32,$A12<=50) ), IFERROR( INDEX('Daily Sales'!$C:$AG, $A12, MATCH(TEXT($B12,"0"),TEXT('Daily Sales'!$C$2:$AG$2,"0"),0) ), ""), "") )} | I12: {=IF($A12="","", IF( OR( AND($A12>=4,$A12<=8), AND($A12>=12,$A12<=19), AND($A12>=28,$A12<=29) ), IFERROR( INDEX('Daily Sales'!$C:$AG, $A12, MATCH(TEXT($B12,"0"),TEXT('Daily Sales'!$C$2:$AG$2,"0"),0) ), ""), "") )} -> 0 | J12: =J11+H12-I12 -> #VALUE!
A13: =IF(E13="","",MATCH(E13,'Daily Sales'!B$4:B$51,0)+3) -> 14 | B13: 46174 | C13: DS26-0601 | D13: {=IF($A13="","",INDEX('Daily Sales'!A:A,$A13))} -> 4-2100 | E13: Sales Food CLUB | F13: =E13 -> Sales Food CLUB | H13: {=IF($A13="","", IF( OR( $A13=23, AND($A13>=32,$A13<=50) ), IFERROR( INDEX('Daily Sales'!$C:$AG, $A13, MATCH(TEXT($B13,"0"),TEXT('Daily Sales'!$C$2:$AG$2,"0"),0) ), ""), "") )} | I13: {=IF($A13="","", IF( OR( AND($A13>=4,$A13<=8), AND($A13>=12,$A13<=19), AND($A13>=28,$A13<=29) ), IFERROR( INDEX('Daily Sales'!$C:$AG, $A13, MATCH(TEXT($B13,"0"),TEXT('Daily Sales'!$C$2:$AG$2,"0"),0) ), ""), "") )} -> 100000 | J13: =J12+H13-I13 -> #VALUE!
A14: =IF(E14="","",MATCH(E14,'Daily Sales'!B$4:B$51,0)+3) -> 15 | B14: 46174 | C14: DS26-0601 | D14: {=IF($A14="","",INDEX('Daily Sales'!A:A,$A14))} -> 4-2300 | E14: Sales Shisa CLUB | F14: =E14 -> Sales Shisa CLUB | H14: {=IF($A14="","", IF( OR( $A14=23, AND($A14>=32,$A14<=50) ), IFERROR( INDEX('Daily Sales'!$C:$AG, $A14, MATCH(TEXT($B14,"0"),TEXT('Daily Sales'!$C$2:$AG$2,"0"),0) ), ""), "") )} | I14: {=IF($A14="","", IF( OR( AND($A14>=4,$A14<=8), AND($A14>=12,$A14<=19), AND($A14>=28,$A14<=29) ), IFERROR( INDEX('Daily Sales'!$C:$AG, $A14, MATCH(TEXT($B14,"0"),TEXT('Daily Sales'!$C$2:$AG$2,"0"),0) ), ""), "") )} -> 0 | J14: =J13+H14-I14 -> #VALUE!
A15: =IF(E15="","",MATCH(E15,'Daily Sales'!B$4:B$51,0)+3) -> 17 | B15: 46174 | C15: DS26-0601 | D15: {=IF($A15="","",INDEX('Daily Sales'!A:A,$A15))} -> 4-2601 | E15: Misc | F15: =E15 -> Misc | H15: {=IF($A15="","", IF( OR( $A15=23, AND($A15>=32,$A15<=50) ), IFERROR( INDEX('Daily Sales'!$C:$AG, $A15, MATCH(TEXT($B15,"0"),TEXT('Daily Sales'!$C$2:$AG$2,"0"),0) ), ""), "") )} | I15: {=IF($A15="","", IF( OR( AND($A15>=4,$A15<=8), AND($A15>=12,$A15<=19), AND($A15>=28,$A15<=29) ), IFERROR( INDEX('Daily Sales'!$C:$AG, $A15, MATCH(TEXT($B15,"0"),TEXT('Daily Sales'!$C$2:$AG$2,"0"),0) ), ""), "") )} -> 0 | J15: =J14+H15-I15 -> #VALUE!
A16: =IF(E16="","",MATCH(E16,'Daily Sales'!B$4:B$51,0)+3) -> 19 | B16: 46174 | C16: DS26-0601 | D16: {=IF($A16="","",INDEX('Daily Sales'!A:A,$A16))} -> 4-2500 | E16: Sales Ticket | F16: =E16 -> Sales Ticket | H16: {=IF($A16="","", IF( OR( $A16=23, AND($A16>=32,$A16<=50) ), IFERROR( INDEX('Daily Sales'!$C:$AG, $A16, MATCH(TEXT($B16,"0"),TEXT('Daily Sales'!$C$2:$AG$2,"0"),0) ), ""), "") )} | I16: {=IF($A16="","", IF( OR( AND($A16>=4,$A16<=8), AND($A16>=12,$A16<=19), AND($A16>=28,$A16<=29) ), IFERROR( INDEX('Daily Sales'!$C:$AG, $A16, MATCH(TEXT($B16,"0"),TEXT('Daily Sales'!$C$2:$AG$2,"0"),0) ), ""), "") )} -> 12404452 | J16: =J15+H16-I16 -> #VALUE!
A17: =IF(E17="","",MATCH(E17,'Daily Sales'!B$4:B$51,0)+3) -> 28 | B17: 46174 | C17: DS26-0601 | D17: {=IF($A17="","",INDEX('Daily Sales'!A:A,$A17))} -> 2-2106 | E17: Service Charges 7% | F17: =E17 -> Service Charges 7% | H17: {=IF($A17="","", IF( OR( $A17=23, AND($A17>=32,$A17<=50) ), IFERROR( INDEX('Daily Sales'!$C:$AG, $A17, MATCH(TEXT($B17,"0"),TEXT('Daily Sales'!$C$2:$AG$2,"0"),0) ), ""), "") )} | I17: {=IF($A17="","", IF( OR( AND($A17>=4,$A17<=8), AND($A17>=12,$A17<=19), AND($A17>=28,$A17<=29) ), IFERROR( INDEX('Daily Sales'!$C:$AG, $A17, MATCH(TEXT($B17,"0"),TEXT('Daily Sales'!$C$2:$AG$2,"0"),0) ), ""), "") )} -> 2752256.6 | J17: =J16+H17-I17 -> #VALUE!
A18: =IF(E18="","",MATCH(E18,'Daily Sales'!B$4:B$51,0)+3) -> 29 | B18: 46174 | C18: DS26-0601 | D18: {=IF($A18="","",INDEX('Daily Sales'!A:A,$A18))} -> 2-3101 | E18: Tax PB1 10% | F18: =E18 -> Tax PB1 10% | H18: {=IF($A18="","", IF( OR( $A18=23, AND($A18>=32,$A18<=50) ), IFERROR( INDEX('Daily Sales'!$C:$AG, $A18, MATCH(TEXT($B18,"0"),TEXT('Daily Sales'!$C$2:$AG$2,"0"),0) ), ""), "") )} | I18: {=IF($A18="","", IF( OR( AND($A18>=4,$A18<=8), AND($A18>=12,$A18<=19), AND($A18>=28,$A18<=29) ), IFERROR( INDEX('Daily Sales'!$C:$AG, $A18, MATCH(TEXT($B18,"0"),TEXT('Daily Sales'!$C$2:$AG$2,"0"),0) ), ""), "") )} -> 4207020.9 | J18: =J17+H18-I18 -> #VALUE!
A19: =IF(E19="","",MATCH(E19,'Daily Sales'!B$4:B$51,0)+3) -> 23 | B19: 46174 | C19: DS26-0601 | D19: {=IF($A19="","",INDEX('Daily Sales'!A:A,$A19))} -> 4-5110 | E19: Discount | F19: =E19 -> Discount | H19: {=IF($A19="","", IF( OR( $A19=23, AND($A19>=32,$A19<=50) ), IFERROR( INDEX('Daily Sales'!$C:$AG, $A19, MATCH(TEXT($B19,"0"),TEXT('Daily Sales'!$C$2:$AG$2,"0"),0) ), ""), "") )} -> 626500 | J19: =J18+H19-I19 -> #VALUE!
A20: =IF(E20="","",MATCH(E20,'Daily Sales'!B$4:B$51,0)+3) -> 32 | B20: 46174 | C20: DS26-0601 | D20: {=IF($A20="","",INDEX('Daily Sales'!A:A,$A20))} -> 1-1119 | E20: Cash IDR | F20: =E20 -> Cash IDR | H20: {=IF($A20="","", IF( OR( $A20=23, AND($A20>=32,$A20<=50) ), IFERROR( INDEX('Daily Sales'!$C:$AG, $A20, MATCH(TEXT($B20,"0"),TEXT('Daily Sales'!$C$2:$AG$2,"0"),0) ), ""), "") )} -> 10502700 | I20: {=IF($A20="","", IF( OR( AND($A20>=4,$A20<=8), AND($A20>=12,$A20<=19), AND($A20>=28,$A20<=29) ), IFERROR( INDEX('Daily Sales'!$C:$AG, $A20, MATCH(TEXT($B20,"0"),TEXT('Daily Sales'!$C$2:$AG$2,"0"),0) ), ""), "") )} | J20: =J19+H20-I20 -> #VALUE!
A21: =IF(E21="","",MATCH(E21,'Daily Sales'!B$4:B$51,0)+3) -> 33 | B21: 46174 | C21: DS26-0601 | D21: {=IF($A21="","",INDEX('Daily Sales'!A:A,$A21))} -> 1-1217 | E21: Bank transfer | F21: =E21 -> Bank transfer | H21: {=IF($A21="","", IF( OR( $A21=23, AND($A21>=32,$A21<=50) ), IFERROR( INDEX('Daily Sales'!$C:$AG, $A21, MATCH(TEXT($B21,"0"),TEXT('Daily Sales'!$C$2:$AG$2,"0"),0) ), ""), "") )} -> 0 | I21: {=IF($A21="","", IF( OR( AND($A21>=4,$A21<=8), AND($A21>=12,$A21<=19), AND($A21>=28,$A21<=29) ), IFERROR( INDEX('Daily Sales'!$C:$AG, $A21, MATCH(TEXT($B21,"0"),TEXT('Daily Sales'!$C$2:$AG$2,"0"),0) ), ""), "") )} | J21: =J20+H21-I21 -> #VALUE!
A22: =IF(E22="","",MATCH(E22,'Daily Sales'!B$4:B$51,0)+3) -> 35 | B22: 46174 | C22: DS26-0601 | D22: {=IF($A22="","",INDEX('Daily Sales'!A:A,$A22))} -> 1-1216 | E22: Cim Niaga TBB | F22: =E22 -> Cim Niaga TBB | H22: {=IF($A22="","", IF( OR( $A22=23, AND($A22>=32,$A22<=50) ), IFERROR( INDEX('Daily Sales'!$C:$AG, $A22, MATCH(TEXT($B22,"0"),TEXT('Daily Sales'!$C$2:$AG$2,"0"),0) ), ""), "") )} -> 0 | I22: {=IF($A22="","", IF( OR( AND($A22>=4,$A22<=8), AND($A22>=12,$A22<=19), AND($A22>=28,$A22<=29) ), IFERROR( INDEX('Daily Sales'!$C:$AG, $A22, MATCH(TEXT($B22,"0"),TEXT('Daily Sales'!$C$2:$AG$2,"0"),0) ), ""), "") )} | J22: =J21+H22-I22 -> #VALUE!
A23: =IF(E23="","",MATCH(E23,'Daily Sales'!B$4:B$51,0)+3) -> 36 | B23: 46174 | C23: DS26-0601 | D23: {=IF($A23="","",INDEX('Daily Sales'!A:A,$A23))} -> 1-1213 | E23: Mandiri Debet | F23: =E23 -> Mandiri Debet | H23: {=IF($A23="","", IF( OR( $A23=23, AND($A23>=32,$A23<=50) ), IFERROR( INDEX('Daily Sales'!$C:$AG, $A23, MATCH(TEXT($B23,"0"),TEXT('Daily Sales'!$C$2:$AG$2,"0"),0) ), ""), "") )} -> 258490 | I23: {=IF($A23="","", IF( OR( AND($A23>=4,$A23<=8), AND($A23>=12,$A23<=19), AND($A23>=28,$A23<=29) ), IFERROR( INDEX('Daily Sales'!$C:$AG, $A23, MATCH(TEXT($B23,"0"),TEXT('Daily Sales'!$C$2:$AG$2,"0"),0) ), ""), "") )} | J23: =J22+H23-I23 -> #VALUE!
A24: =IF(E24="","",MATCH(E24,'Daily Sales'!B$4:B$51,0)+3) -> 37 | B24: 46174 | C24: DS26-0601 | D24: {=IF($A24="","",INDEX('Daily Sales'!A:A,$A24))} -> 1-1213 | E24: Mandiri CC | F24: =E24 -> Mandiri CC | H24: {=IF($A24="","", IF( OR( $A24=23, AND($A24>=32,$A24<=50) ), IFERROR( INDEX('Daily Sales'!$C:$AG, $A24, MATCH(TEXT($B24,"0"),TEXT('Daily Sales'!$C$2:$AG$2,"0"),0) ), ""), "") )} -> 24448395 | I24: {=IF($A24="","", IF( OR( AND($A24>=4,$A24<=8), AND($A24>=12,$A24<=19), AND($A24>=28,$A24<=29) ), IFERROR( INDEX('Daily Sales'!$C:$AG, $A24, MATCH(TEXT($B24,"0"),TEXT('Daily Sales'!$C$2:$AG$2,"0"),0) ), ""), "") )} | J24: =J23+H24-I24 -> #VALUE!
A25: =IF(E25="","",MATCH(E25,'Daily Sales'!B$4:B$51,0)+3) -> 38 | B25: 46174 | C25: DS26-0601 | D25: {=IF($A25="","",INDEX('Daily Sales'!A:A,$A25))} -> 1-1213 | E25: Mandiri NPG | F25: =E25 -> Mandiri NPG | H25: {=IF($A25="","", IF( OR( $A25=23, AND($A25>=32,$A25<=50) ), IFERROR( INDEX('Daily Sales'!$C:$AG, $A25, MATCH(TEXT($B25,"0"),TEXT('Daily Sales'!$C$2:$AG$2,"0"),0) ), ""), "") )} -> 1435490 | I25: {=IF($A25="","", IF( OR( AND($A25>=4,$A25<=8), AND($A25>=12,$A25<=19), AND($A25>=28,$A25<=29) ), IFERROR( INDEX('Daily Sales'!$C:$AG, $A25, MATCH(TEXT($B25,"0"),TEXT('Daily Sales'!$C$2:$AG$2,"0"),0) ), ""), "") )} | J25: =J24+H25-I25 -> #VALUE!
A26: =IF(E26="","",MATCH(E26,'Daily Sales'!B$4:B$51,0)+3) -> 39 | B26: 46174 | C26: DS26-0601 | D26: {=IF($A26="","",INDEX('Daily Sales'!A:A,$A26))} -> 1-1213 | E26: Mandiri QR | F26: =E26 -> Mandiri QR | H26: {=IF($A26="","", IF( OR( $A26=23, AND($A26>=32,$A26<=50) ), IFERROR( INDEX('Daily Sales'!$C:$AG, $A26, MATCH(TEXT($B26,"0"),TEXT('Daily Sales'!$C$2:$AG$2,"0"),0) ), ""), "") )} -> 2350833 | I26: {=IF($A26="","", IF( OR( AND($A26>=4,$A26<=8), AND($A26>=12,$A26<=19), AND($A26>=28,$A26<=29) ), IFERROR( INDEX('Daily Sales'!$C:$AG, $A26, MATCH(TEXT($B26,"0"),TEXT('Daily Sales'!$C$2:$AG$2,"0"),0) ), ""), "") )} | J26: =J25+H26-I26 -> #VALUE!
A27: =IF(E27="","",MATCH(E27,'Daily Sales'!B$4:B$51,0)+3) -> 40 | B27: 46174 | C27: DS26-0601 | D27: {=IF($A27="","",INDEX('Daily Sales'!A:A,$A27))} -> 1-1217 | E27: BCA CC | F27: =E27 -> BCA CC | H27: {=IF($A27="","", IF( OR( $A27=23, AND($A27>=32,$A27<=50) ), IFERROR( INDEX('Daily Sales'!$C:$AG, $A27, MATCH(TEXT($B27,"0"),TEXT('Daily Sales'!$C$2:$AG$2,"0"),0) ), ""), "") )} -> 6579340 | I27: {=IF($A27="","", IF( OR( AND($A27>=4,$A27<=8), AND($A27>=12,$A27<=19), AND($A27>=28,$A27<=29) ), IFERROR( INDEX('Daily Sales'!$C:$AG, $A27, MATCH(TEXT($B27,"0"),TEXT('Daily Sales'!$C$2:$AG$2,"0"),0) ), ""), "") )} | J27: =J26+H27-I27 -> #VALUE!
A28: =IF(E28="","",MATCH(E28,'Daily Sales'!B$4:B$51,0)+3) -> 41 | B28: 46174 | C28: DS26-0601 | D28: {=IF($A28="","",INDEX('Daily Sales'!A:A,$A28))} -> 1-1217 | E28: BCA debt | F28: =E28 -> BCA debt | H28: {=IF($A28="","", IF( OR( $A28=23, AND($A28>=32,$A28<=50) ), IFERROR( INDEX('Daily Sales'!$C:$AG, $A28, MATCH(TEXT($B28,"0"),TEXT('Daily Sales'!$C$2:$AG$2,"0"),0) ), ""), "") )} -> 164780 | I28: {=IF($A28="","", IF( OR( AND($A28>=4,$A28<=8), AND($A28>=12,$A28<=19), AND($A28>=28,$A28<=29) ), IFERROR( INDEX('Daily Sales'!$C:$AG, $A28, MATCH(TEXT($B28,"0"),TEXT('Daily Sales'!$C$2:$AG$2,"0"),0) ), ""), "") )} | J28: =J27+H28-I28 -> #VALUE!
A29: =IF(E29="","",MATCH(E29,'Daily Sales'!B$4:B$51,0)+3) -> 42 | B29: 46174 | C29: DS26-0601 | D29: {=IF($A29="","",INDEX('Daily Sales'!A:A,$A29))} -> 1-1217 | E29: BCA QR | F29: =E29 -> BCA QR | H29: {=IF($A29="","", IF( OR( $A29=23, AND($A29>=32,$A29<=50) ), IFERROR( INDEX('Daily Sales'!$C:$AG, $A29, MATCH(TEXT($B29,"0"),TEXT('Daily Sales'!$C$2:$AG$2,"0"),0) ), ""), "") )} -> 294250 | I29: {=IF($A29="","", IF( OR( AND($A29>=4,$A29<=8), AND($A29>=12,$A29<=19), AND($A29>=28,$A29<=29) ), IFERROR( INDEX('Daily Sales'!$C:$AG, $A29, MATCH(TEXT($B29,"0"),TEXT('Daily Sales'!$C$2:$AG$2,"0"),0) ), ""), "") )} | J29: =J28+H29-I29 -> #VALUE!
A30: =IF(E30="","",MATCH(E30,'Daily Sales'!B$4:B$51,0)+3) -> 43 | B30: 46174 | C30: DS26-0601 | D30: {=IF($A30="","",INDEX('Daily Sales'!A:A,$A30))} -> 1-1214 | E30: Bank BRI DEBET | F30: =E30 -> Bank BRI DEBET | H30: {=IF($A30="","", IF( OR( $A30=23, AND($A30>=32,$A30<=50) ), IFERROR( INDEX('Daily Sales'!$C:$AG, $A30, MATCH(TEXT($B30,"0"),TEXT('Daily Sales'!$C$2:$AG$2,"0"),0) ), ""), "") )} -> 0 | I30: {=IF($A30="","", IF( OR( AND($A30>=4,$A30<=8), AND($A30>=12,$A30<=19), AND($A30>=28,$A30<=29) ), IFERROR( INDEX('Daily Sales'!$C:$AG, $A30, MATCH(TEXT($B30,"0"),TEXT('Daily Sales'!$C$2:$AG$2,"0"),0) ), ""), "") )} | J30: =J29+H30-I30 -> #VALUE!
A31: =IF(E31="","",MATCH(E31,'Daily Sales'!B$4:B$51,0)+3) -> 44 | B31: 46174 | C31: DS26-0601 | D31: {=IF($A31="","",INDEX('Daily Sales'!A:A,$A31))} -> 1-1214 | E31: Bank BRI CC | F31: =E31 -> Bank BRI CC | H31: {=IF($A31="","", IF( OR( $A31=23, AND($A31>=32,$A31<=50) ), IFERROR( INDEX('Daily Sales'!$C:$AG, $A31, MATCH(TEXT($B31,"0"),TEXT('Daily Sales'!$C$2:$AG$2,"0"),0) ), ""), "") )} -> 0 | I31: {=IF($A31="","", IF( OR( AND($A31>=4,$A31<=8), AND($A31>=12,$A31<=19), AND($A31>=28,$A31<=29) ), IFERROR( INDEX('Daily Sales'!$C:$AG, $A31, MATCH(TEXT($B31,"0"),TEXT('Daily Sales'!$C$2:$AG$2,"0"),0) ), ""), "") )} | J31: =J30+H31-I31 -> #VALUE!
... A37: =IF(E37="","",MATCH(E37,'Daily Sales'!B$4:B$51,0)+3) -> 50 | B37: 46174 | C37: DS26-0601 | D37: {=IF($A37="","",INDEX('Daily Sales'!A:A,$A37))} -> 2-2110 | E37: Cash Short/Over | F37: =E37 -> Cash Short/Over | H37: {=IF($A37="","", IF( OR( $A37=23, AND($A37>=32,$A37<=50) ), IFERROR( INDEX('Daily Sales'!$C:$AG, $A37, MATCH(TEXT($B37,"0"),TEXT('Daily Sales'!$C$2:$AG$2,"0"),0) ), ""), "") )} -> 489.5 | I37: {=IF($A37="","", IF( OR( AND($A37>=4,$A37<=8), AND($A37>=12,$A37<=19), AND($A37>=28,$A37<=29) ), IFERROR( INDEX('Daily Sales'!$C:$AG, $A37, MATCH(TEXT($B37,"0"),TEXT('Daily Sales'!$C$2:$AG$2,"0"),0) ), ""), "") )} | J37: =J36+H37-I37 -> #VALUE!
A38: =IF(E38="","",MATCH(E38,'Daily Sales'!B$4:B$51,0)+3) | D38: {=IF($A38="","",INDEX('Daily Sales'!A:A,$A38))} | F38: =E38 -> 0 | H38: {=IF($A38="","", IF( OR( $A38=23, AND($A38>=32,$A38<=50) ), IFERROR( INDEX('Daily Sales'!$C:$AG, $A38, MATCH(TEXT($B38,"0"),TEXT('Daily Sales'!$C$2:$AG$2,"0"),0) ), ""), "") )} | I38: {=IF($A38="","", IF( OR( AND($A38>=4,$A38<=8), AND($A38>=12,$A38<=19), AND($A38>=28,$A38<=29) ), IFERROR( INDEX('Daily Sales'!$C:$AG, $A38, MATCH(TEXT($B38,"0"),TEXT('Daily Sales'!$C$2:$AG$2,"0"),0) ), ""), "") )} | J38: =J37+H38-I38 -> #VALUE!
A39: =IF(E39="","",MATCH(E39,'Daily Sales'!B$4:B$51,0)+3) -> 4 | B39: 46175 | C39: DS26-0602 | D39: {=IF($A39="","",INDEX('Daily Sales'!A:A,$A39))} -> 4-2100 | E39: Sales Food TERRACE | F39: =E39 -> Sales Food TERRACE | H39: {=IF($A39="","", IF( OR( $A39=23, AND($A39>=32,$A39<=50) ), IFERROR( INDEX('Daily Sales'!$C:$AG, $A39, MATCH(TEXT($B39,"0"),TEXT('Daily Sales'!$C$2:$AG$2,"0"),0) ), ""), "") )} | I39: {=IF($A39="","", IF( OR( AND($A39>=4,$A39<=8), AND($A39>=12,$A39<=19), AND($A39>=28,$A39<=29) ), IFERROR( INDEX('Daily Sales'!$C:$AG, $A39, MATCH(TEXT($B39,"0"),TEXT('Daily Sales'!$C$2:$AG$2,"0"),0) ), ""), "") )} -> 3590000 | J39: =J38+H39-I39 -> #VALUE!
A40: =IF(E40="","",MATCH(E40,'Daily Sales'!B$4:B$51,0)+3) -> 5 | B40: 46175 | C40: DS26-0602 | D40: {=IF($A40="","",INDEX('Daily Sales'!A:A,$A40))} -> 4-2200 | E40: Sales Beverages TERRACE | F40: =E40 -> Sales Beverages TERRACE | H40: {=IF($A40="","", IF( OR( $A40=23, AND($A40>=32,$A40<=50) ), IFERROR( INDEX('Daily Sales'!$C:$AG, $A40, MATCH(TEXT($B40,"0"),TEXT('Daily Sales'!$C$2:$AG$2,"0"),0) ), ""), "") )} | I40: {=IF($A40="","", IF( OR( AND($A40>=4,$A40<=8), AND($A40>=12,$A40<=19), AND($A40>=28,$A40<=29) ), IFERROR( INDEX('Daily Sales'!$C:$AG, $A40, MATCH(TEXT($B40,"0"),TEXT('Daily Sales'!$C$2:$AG$2,"0"),0) ), ""), "") )} -> 2740000 | J40: =J39+H40-I40 -> #VALUE!
A41: =IF(E41="","",MATCH(E41,'Daily Sales'!B$4:B$51,0)+3) -> 6 | B41: 46175 | C41: DS26-0602 | D41: {=IF($A41="","",INDEX('Daily Sales'!A:A,$A41))} -> 4-2400 | E41: Sales Cigarette TERRACE | F41: =E41 -> Sales Cigarette TERRACE | H41: {=IF($A41="","", IF( OR( $A41=23, AND($A41>=32,$A41<=50) ), IFERROR( INDEX('Daily Sales'!$C:$AG, $A41, MATCH(TEXT($B41,"0"),TEXT('Daily Sales'!$C$2:$AG$2,"0"),0) ), ""), "") )} | I41: {=IF($A41="","", IF( OR( AND($A41>=4,$A41<=8), AND($A41>=12,$A41<=19), AND($A41>=28,$A41<=29) ), IFERROR( INDEX('Daily Sales'!$C:$AG, $A41, MATCH(TEXT($B41,"0"),TEXT('Daily Sales'!$C$2:$AG$2,"0"),0) ), ""), "") )} -> 0 | J41: =J40+H41-I41 -> #VALUE!
A42: =IF(E42="","",MATCH(E42,'Daily Sales'!B$4:B$51,0)+3) -> 7 | B42: 46175 | C42: DS26-0602 | D42: {=IF($A42="","",INDEX('Daily Sales'!A:A,$A42))} -> 4-2300 | E42: Sales Shisa TERRACE | F42: =E42 -> Sales Shisa TERRACE | H42: {=IF($A42="","", IF( OR( $A42=23, AND($A42>=32,$A42<=50) ), IFERROR( INDEX('Daily Sales'!$C:$AG, $A42, MATCH(TEXT($B42,"0"),TEXT('Daily Sales'!$C$2:$AG$2,"0"),0) ), ""), "") )} | I42: {=IF($A42="","", IF( OR( AND($A42>=4,$A42<=8), AND($A42>=12,$A42<=19), AND($A42>=28,$A42<=29) ), IFERROR( INDEX('Daily Sales'!$C:$AG, $A42, MATCH(TEXT($B42,"0"),TEXT('Daily Sales'!$C$2:$AG$2,"0"),0) ), ""), "") )} -> 0 | J42: =J41+H42-I42 -> #VALUE!
A43: =IF(E43="","",MATCH(E43,'Daily Sales'!B$4:B$51,0)+3) -> 12 | B43: 46175 | C43: DS26-0602 | D43: {=IF($A43="","",INDEX('Daily Sales'!A:A,$A43))} -> 4-2200 | E43: Sales Beverages CLUB | F43: =E43 -> Sales Beverages CLUB | H43: {=IF($A43="","", IF( OR( $A43=23, AND($A43>=32,$A43<=50) ), IFERROR( INDEX('Daily Sales'!$C:$AG, $A43, MATCH(TEXT($B43,"0"),TEXT('Daily Sales'!$C$2:$AG$2,"0"),0) ), ""), "") )} | I43: {=IF($A43="","", IF( OR( AND($A43>=4,$A43<=8), AND($A43>=12,$A43<=19), AND($A43>=28,$A43<=29) ), IFERROR( INDEX('Daily Sales'!$C:$AG, $A43, MATCH(TEXT($B43,"0"),TEXT('Daily Sales'!$C$2:$AG$2,"0"),0) ), ""), "") )} -> 27335000 | J43: =J42+H43-I43 -> #VALUE!
A44: =IF(E44="","",MATCH(E44,'Daily Sales'!B$4:B$51,0)+3) -> 13 | B44: 46175 | C44: DS26-0602 | D44: {=IF($A44="","",INDEX('Daily Sales'!A:A,$A44))} -> 4-2400 | E44: Sales Cigarette CLUB | F44: =E44 -> Sales Cigarette CLUB | H44: {=IF($A44="","", IF( OR( $A44=23, AND($A44>=32,$A44<=50) ), IFERROR( INDEX('Daily Sales'!$C:$AG, $A44, MATCH(TEXT($B44,"0"),TEXT('Daily Sales'!$C$2:$AG$2,"0"),0) ), ""), "") )} | I44: {=IF($A44="","", IF( OR( AND($A44>=4,$A44<=8), AND($A44>=12,$A44<=19), AND($A44>=28,$A44<=29) ), IFERROR( INDEX('Daily Sales'!$C:$AG, $A44, MATCH(TEXT($B44,"0"),TEXT('Daily Sales'!$C$2:$AG$2,"0"),0) ), ""), "") )} -> 820000 | J44: =J43+H44-I44 -> #VALUE!
A45: =IF(E45="","",MATCH(E45,'Daily Sales'!B$4:B$51,0)+3) -> 14 | B45: 46175 | C45: DS26-0602 | D45: {=IF($A45="","",INDEX('Daily Sales'!A:A,$A45))} -> 4-2100 | E45: Sales Food CLUB | F45: =E45 -> Sales Food CLUB | H45: {=IF($A45="","", IF( OR( $A45=23, AND($A45>=32,$A45<=50) ), IFERROR( INDEX('Daily Sales'!$C:$AG, $A45, MATCH(TEXT($B45,"0"),TEXT('Daily Sales'!$C$2:$AG$2,"0"),0) ), ""), "") )} | I45: {=IF($A45="","", IF( OR( AND($A45>=4,$A45<=8), AND($A45>=12,$A45<=19), AND($A45>=28,$A45<=29) ), IFERROR( INDEX('Daily Sales'!$C:$AG, $A45, MATCH(TEXT($B45,"0"),TEXT('Daily Sales'!$C$2:$AG$2,"0"),0) ), ""), "") )} -> 350000 | J45: =J44+H45-I45 -> #VALUE!
...

Sheet TB
B1: TRIAL BALANCE
B2: =GL!I1 -> PT TAMAN BINTANG BALI
B3: =GL!I3 -> MONTH OF June 2026
B4: DESCRIPTION | D4: QTY | E4: TRIAL BALANCF | I4: TRIAL BALANCE (MTD) | N4: TRIAL BALANCE (YTD) | P4: ADJUSMENT ENTRY | R4: ADJUSTED ENTRY | T4: PROFIT AND LOST | V4: EQUITY | X4: BALANCE
E5: DB | F5: CR | I5: DB | J5: CR | N5: DB | O5: CR | P5: DB | Q5: CR | R5: DB | S5: CR | T5: DB | U5: CR | V5: DB | W5: CR | X5: DB | Y5: CR
B7: 1-0000 | C7: Assets
B8: 1-1000 | C8: Current Assets
B9: 1-1100 | C9: Cash | E9: =SUM(E10:E11) -> 638838402 | F9: =SUM(F10:F11) -> 642880644 | I9: =SUM(I10:I11) -> 10730518 | J9: =SUM(J10:J11) -> 14772760 | K9: =SUM(K10:K11) -> 0 | L9: =SUM(L10:L11) -> 25194675 | M9: =SUM(M10:M11) -> 0 | N9: =SUM(N10:N11) -> 21152433 | O9: =SUM(O10:O11) -> 0 | P9: =SUM(P10:P11) -> 0 | ... Y9: =SUM(Y10:Y11) -> 0
B10: 1-1106 | C10: Petty Cash IDR - on General Cashier | E10: =SUMIF(GL!$D$6:$D$6487,B10,GL!$H$6:$H$6487) -> 326805581 | F10: =SUMIF(GL!$D$6:$D$6487,B10,GL!$I$6:$I$6487) -> 316075063 | I10: =IF(E10>F10,E10-F10,0) -> 10730518 | J10: =IF(F10>E10,F10-E10,0) -> 0 | L10: 5921915 | N10: =IF(I10+L10>J10+M10,(I10+L10)-(J10+M10),0) -> 16652433 | O10: =IF(J10+M10>I10+L10,(J10+M10)-(I10+L10),0) -> 0 | P10: =SUMIF(GL!$D$6488:$D$6532,B10,GL!$H$6488:$H$6532) -> 0 | Q10: =SUMIF(GL!$D$6408:$D$6452,B10,GL!$I$6408:$I$6452) -> 0 | R10: =P10+N10 -> 16652433 | S10: =Q10+O10 -> 0 | X10: =IF(R10>S10,R10-S10,0) -> 16652433 | Y10: =IF(S10>R10,S10-R10,0) -> 0 | Z10: V | AA10: 16652433 | AB10: =X10-AA10 -> 0
B11: 1-1119 | C11: Petty Cash IDR - on Bar Cashier | E11: =SUMIF(GL!$D$6:$D$6487,B11,GL!$H$6:$H$6487) -> 312032821 | F11: =SUMIF(GL!$D$6:$D$6487,B11,GL!$I$6:$I$6487) -> 326805581 | I11: =IF(E11>F11,E11-F11,0) -> 0 | J11: =IF(F11>E11,F11-E11,0) -> 14772760 | L11: 19272760 | N11: =IF(I11+L11>J11+M11,(I11+L11)-(J11+M11),0) -> 4500000 | O11: =IF(J11+M11>I11+L11,(J11+M11)-(I11+L11),0) -> 0 | P11: =SUMIF(GL!$D$6488:$D$6532,B11,GL!$H$6488:$H$6532) -> 0 | Q11: =SUMIF(GL!$D$6408:$D$6452,B11,GL!$I$6408:$I$6452) -> 0 | R11: =P11+N11 -> 4500000 | S11: =Q11+O11 -> 0 | X11: =IF(R11>S11,R11-S11,0) -> 4500000 | Y11: =IF(S11>R11,S11-R11,0) -> 0
B12: 1-1120 | C12: Cash in banks | E12: =SUM(E13:E22) -> 3.3949518e+09 | F12: =SUM(F13:F22) -> 3.5681557e+09 | G12: =SUM(G13:G22) -> 0 | H12: =SUM(H13:H22) -> 0 | I12: =SUM(I13:I22) -> 1400779 | J12: =SUM(J13:J22) -> 1.7460464e+08 | K12: =SUM(K13:K22) -> 0 | L12: =SUM(L13:L22) -> 496257319 | ... Y12: =SUM(Y13:Y22) -> 0
B13: 1-1121 | C13: Mandiri KBB 2 | E13: =SUMIF(GL!$D$6:$D$6487,B13,GL!$H$6:$H$6487) -> 0 | F13: =SUMIF(GL!$D$6:$D$6487,B13,GL!$I$6:$I$6487) -> 0 | I13: =IF(E13>F13,E13-F13,0) -> 0 | J13: =IF(F13>E13,F13-E13,0) -> 0 | N13: =IF(I13+L13>J13+M13,(I13+L13)-(J13+M13),0) -> 0 | O13: =IF(J13+M13>I13+L13,(J13+M13)-(I13+L13),0) -> 0 | P13: =SUMIF(GL!$D$6488:$D$6532,B13,GL!$H$6488:$H$6532) -> 0 | Q13: =SUMIF(GL!$D$6408:$D$6452,B13,GL!$I$6408:$I$6452) -> 0 | R13: =P13+N13 -> 0 | S13: =Q13+O13 -> 0 | X13: =IF(R13>S13,R13-S13,0) -> 0 | Y13: =IF(S13>R13,S13-R13,0) -> 0
B14: 1-1122 | C14: Mandiri TBB USD | E14: =SUMIF(GL!$D$6:$D$6487,B14,GL!$H$6:$H$6487) -> 223920000 | F14: =SUMIF(GL!$D$6:$D$6487,B14,GL!$I$6:$I$6487) -> 223703177 | I14: =IF(E14>F14,E14-F14,0) -> 216823 | J14: =IF(F14>E14,F14-E14,0) -> 0 | L14: 9215363 | N14: =IF(I14+L14>J14+M14,(I14+L14)-(J14+M14),0) -> 9432186 | O14: =IF(J14+M14>I14+L14,(J14+M14)-(I14+L14),0) -> 0 | P14: =SUMIF(GL!$D$6488:$D$6532,B14,GL!$H$6488:$H$6532) -> 0 | Q14: =SUMIF(GL!$D$6408:$D$6452,B14,GL!$I$6408:$I$6452) -> 0 | R14: =P14+N14 -> 9432186 | S14: =Q14+O14 -> 0 | X14: =IF(R14>S14,R14-S14,0) -> 9432186 | Y14: =IF(S14>R14,S14-R14,0) -> 0 | Z14: V | AA14: =528.71*17840 -> 9432186.4 | AB14: =X14-AA14 -> -0.4
B15: 1-1123 | C15: Mandiri TBB IDR | E15: =SUMIF(GL!$D$6:$D$6487,B15,GL!$H$6:$H$6487) -> 1.8782882e+09 | F15: =SUMIF(GL!$D$6:$D$6487,B15,GL!$I$6:$I$6487) -> 1.9757022e+09 | I15: =IF(E15>F15,E15-F15,0) -> 0 | J15: =IF(F15>E15,F15-E15,0) -> 97413971 | L15: 98857588 | N15: =IF(I15+L15>J15+M15,(I15+L15)-(J15+M15),0) -> 1443616.9 | O15: =IF(J15+M15>I15+L15,(J15+M15)-(I15+L15),0) -> 0 | P15: =SUMIF(GL!$D$6488:$D$6532,B15,GL!$H$6488:$H$6532) -> 0 | Q15: =SUMIF(GL!$D$6408:$D$6452,B15,GL!$I$6408:$I$6452) -> 0 | R15: =P15+N15 -> 1443616.9 | S15: =Q15+O15 -> 0 | X15: =IF(R15>S15,R15-S15,0) -> 1443616.9 | Y15: =IF(S15>R15,S15-R15,0) -> 0 | Z15: V | AA15: 1443616.9 | AB15: =X15-Y15-AA15 -> -0.001999073
B16: 1-1124 | C16: BANK BRI | E16: =SUMIF(GL!$D$6:$D$6487,B16,GL!$H$6:$H$6487) -> 16898675 | F16: =SUMIF(GL!$D$6:$D$6487,B16,GL!$I$6:$I$6487) -> 18557500 | I16: =IF(E16>F16,E16-F16,0) -> 0 | J16: =IF(F16>E16,F16-E16,0) -> 1658825 | L16: 2008743 | N16: =IF(I16+L16>J16+M16,(I16+L16)-(J16+M16),0) -> 349918 | O16: =IF(J16+M16>I16+L16,(J16+M16)-(I16+L16),0) -> 0 | P16: =SUMIF(GL!$D$6488:$D$6532,B16,GL!$H$6488:$H$6532) -> 0 | Q16: =SUMIF(GL!$D$6408:$D$6452,B16,GL!$I$6408:$I$6452) -> 0 | R16: =P16+N16 -> 349918 | S16: =Q16+O16 -> 0 | X16: =IF(R16>S16,R16-S16,0) -> 349918 | Y16: =IF(S16>R16,S16-R16,0) -> 0 | Z16: V | AA16: 349918 | AB16: =X16-Y16-AA16 -> 0.0019999966
B17: 1-1125 | C17: Mandiri GRAB | E17: =SUMIF(GL!$D$6:$D$6487,B17,GL!$H$6:$H$6487) -> 8549673 | F17: =SUMIF(GL!$D$6:$D$6487,B17,GL!$I$6:$I$6487) -> 8977500 | I17: =IF(E17>F17,E17-F17,0) -> 0 | J17: =IF(F17>E17,F17-E17,0) -> 427827 | L17: 1452954 | N17: =IF(I17+L17>J17+M17,(I17+L17)-(J17+M17),0) -> 1025127 | O17: =IF(J17+M17>I17+L17,(J17+M17)-(I17+L17),0) -> 0 | P17: =SUMIF(GL!$D$6488:$D$6532,B17,GL!$H$6488:$H$6532) -> 0 | Q17: =SUMIF(GL!$D$6408:$D$6452,B17,GL!$I$6408:$I$6452) -> 0 | R17: =P17+N17 -> 1025127 | S17: =Q17+O17 -> 0 | X17: =IF(R17>S17,R17-S17,0) -> 1025127 | Y17: =IF(S17>R17,S17-R17,0) -> 0 | Z17: V | AA17: 1025127 | AB17: =X17-Y17-AA17 -> 0
B18: 1-1126 | C18: Cimb Niaga TBB | E18: =SUMIF(GL!$D$6:$D$6487,B18,GL!$H$6:$H$6487) -> 102154080 | F18: =SUMIF(GL!$D$6:$D$6487,B18,GL!$I$6:$I$6487) -> 102157500 | I18: =IF(E18>F18,E18-F18,0) -> 0 | J18: =IF(F18>E18,F18-E18,0) -> 3420 | L18: 1058653 | N18: =IF(I18+L18>J18+M18,(I18+L18)-(J18+M18),0) -> 1055233 | O18: =IF(J18+M18>I18+L18,(J18+M18)-(I18+L18),0) -> 0 | P18: =SUMIF(GL!$D$6488:$D$6532,B18,GL!$H$6488:$H$6532) -> 0 | Q18: =SUMIF(GL!$D$6408:$D$6452,B18,GL!$I$6408:$I$6452) -> 0 | R18: =P18+N18 -> 1055233 | S18: =Q18+O18 -> 0 | X18: =IF(R18>S18,R18-S18,0) -> 1055233 | Y18: =IF(S18>R18,S18-R18,0) -> 0 | Z18: V | AA18: 1055233.4 | AB18: =X18-AA18 -> -0.43
B19: 1-1127 | C19: BCA TBB | E19: =SUMIF(GL!$D$6:$D$6487,B19,GL!$H$6:$H$6487) -> 1.1633698e+09 | F19: =SUMIF(GL!$D$6:$D$6487,B19,GL!$I$6:$I$6487) -> 1238470370 | I19: =IF(E19>F19,E19-F19,0) -> 0 | J19: =IF(F19>E19,F19-E19,0) -> 75100595 | L19: 75507728 | N19: =IF(I19+L19>J19+M19,(I19+L19)-(J19+M19),0) -> 407132.89 | O19: =IF(J19+M19>I19+L19,(J19+M19)-(I19+L19),0) -> 0 | P19: =SUMIF(GL!$D$6488:$D$6532,B19,GL!$H$6488:$H$6532) -> 0 | Q19: =SUMIF(GL!$D$6408:$D$6452,B19,GL!$I$6408:$I$6452) -> 0 | R19: =P19+N19 -> 407132.89 | S19: =Q19+O19 -> 0 | X19: =IF(R19>S19,R19-S19,0) -> 407132.89 | Y19: =IF(S19>R19,S19-R19,0) -> 0 | Z19: V | AA19: 407132.89 | AB19: =X19-Y19-AA19 -> 0.0019999599
B20: 1-1128 | C20: MEGA BANK | E20: =SUMIF(GL!$D$6:$D$6487,B20,GL!$H$6:$H$6487) -> 0 | F20: =SUMIF(GL!$D$6:$D$6487,B20,GL!$I$6:$I$6487) -> 0 | I20: =IF(E20>F20,E20-F20,0) -> 0 | J20: =IF(F20>E20,F20-E20,0) -> 0 | N20: =IF(I20+L20>J20+M20,(I20+L20)-(J20+M20),0) -> 0 | O20: =IF(J20+M20>I20+L20,(J20+M20)-(I20+L20),0) -> 0 | P20: =SUMIF(GL!$D$6488:$D$6532,B20,GL!$H$6488:$H$6532) -> 0 | Q20: =SUMIF(GL!$D$6408:$D$6452,B20,GL!$I$6408:$I$6452) -> 0 | R20: =P20+N20 -> 0 | S20: =Q20+O20 -> 0 | X20: =IF(R20>S20,R20-S20,0) -> 0 | Y20: =IF(S20>R20,S20-R20,0) -> 0
B21: 1-1129 | C21: STARXP | E21: =SUMIF(GL!$D$6:$D$6487,B21,GL!$H$6:$H$6487) -> 1771385 | F21: =SUMIF(GL!$D$6:$D$6487,B21,GL!$I$6:$I$6487) -> 587429 | I21: =IF(E21>F21,E21-F21,0) -> 1183956 | J21: =IF(F21>E21,F21-E21,0) -> 0 | L21: 308156290 | N21: =IF(I21+L21>J21+M21,(I21+L21)-(J21+M21),0) -> 309340246 | O21: =IF(J21+M21>I21+L21,(J21+M21)-(I21+L21),0) -> 0 | P21: =SUMIF(GL!$D$6488:$D$6532,B21,GL!$H$6488:$H$6532) -> 0 | Q21: =SUMIF(GL!$D$6408:$D$6452,B21,GL!$I$6408:$I$6452) -> 0 | R21: =P21+N21 -> 309340246 | S21: =Q21+O21 -> 0 | X21: =IF(R21>S21,R21-S21,0) -> 309340246 | Y21: =IF(S21>R21,S21-R21,0) -> 0
B22: 1-1130 | C22: BPR DEWATA CHANDRADANA | E22: =SUMIF(GL!$D$6:$D$6487,B22,GL!$H$6:$H$6487) -> 0 | F22: =SUMIF(GL!$D$6:$D$6487,B22,GL!$I$6:$I$6487) -> 0 | I22: =IF(E22>F22,E22-F22,0) -> 0 | J22: =IF(F22>E22,F22-E22,0) -> 0 | N22: =IF(I22+L22>J22+M22,(I22+L22)-(J22+M22),0) -> 0 | O22: =IF(J22+M22>I22+L22,(J22+M22)-(I22+L22),0) -> 0 | P22: =SUMIF(GL!$D$6488:$D$6532,B22,GL!$H$6488:$H$6532) -> 0 | Q22: =SUMIF(GL!$D$6408:$D$6452,B22,GL!$I$6408:$I$6452) -> 0 | R22: =P22+N22 -> 0 | S22: =Q22+O22 -> 0 | X22: =IF(R22>S22,R22-S22,0) -> 0 | Y22: =IF(S22>R22,S22-R22,0) -> 0
B23: 1-1199 | C23: Total Cash and Cash At Bank | E23: =E12+E9 -> 4.0337902e+09 | F23: =F12+F9 -> 4.2110363e+09 | I23: =I12+I9 -> 12131297 | J23: =J12+J9 -> 1.893774e+08 | L23: =L9+L12 -> 521451994 | M23: =M9+M12 -> 0 | N23: =N12+N9 -> 3.4420589e+08 | O23: =O12+O9 -> 0 | P23: =P12+P9 -> 0 | Q23: =Q12+Q9 -> 0 | R23: =R12+R9 -> 3.4420589e+08 | S23: =S12+S9 -> 0 | T23: =T12+T9 -> 0 | U23: =U12+U9 -> 0 | ... Y23: =Y12+Y9 -> 0
B25: 1-1200 | C25: Account Receivables | E25: =SUM(E26:E28) -> 52938163 | F25: =SUM(F26:F28) -> 65886554 | G25: =SUM(G26:G28) -> 0 | H25: =SUM(H26:H28) -> 0 | I25: =SUM(I26:I28) -> 0 | J25: =SUM(J26:J28) -> 12948391 | K25: =SUM(K26:K28) -> 0 | L25: =SUM(L26:L28) -> 120303822 | ... Y25: =SUM(Y26:Y28) -> 0
B26: 1-1201 | C26: Accounts receivable Trade | E26: =SUMIF(GL!$D$6:$D$6487,B26,GL!$H$6:$H$6487) -> 0 | F26: =SUMIF(GL!$D$6:$D$6487,B26,GL!$I$6:$I$6487) -> 0 | I26: =IF(E26>F26,E26-F26,0) -> 0 | J26: =IF(F26>E26,F26-E26,0) -> 0 | N26: =IF(I26+L26>J26+M26,(I26+L26)-(J26+M26),0) -> 0 | O26: =IF(J26+M26>I26+L26,(J26+M26)-(I26+L26),0) -> 0 | P26: =SUMIF(GL!$D$6488:$D$6532,B26,GL!$H$6488:$H$6532) -> 0 | Q26: =SUMIF(GL!$D$6408:$D$6452,B26,GL!$I$6408:$I$6452) -> 0 | R26: =P26+N26 -> 0 | S26: =Q26+O26 -> 0 | X26: =IF(R26>S26,R26-S26,0) -> 0 | Y26: =IF(S26>R26,S26-R26,0) -> 0
B27: 1-1202 | C27: City Ledger | E27: =SUMIF(GL!$D$6:$D$6487,B27,GL!$H$6:$H$6487) -> 23626023 | F27: =SUMIF(GL!$D$6:$D$6487,B27,GL!$I$6:$I$6487) -> 23957403 | I27: =IF(E27>F27,E27-F27,0) -> 0 | J27: =IF(F27>E27,F27-E27,0) -> 331380 | L27: 81266358 | N27: =IF(I27+L27>J27+M27,(I27+L27)-(J27+M27),0) -> 80934978 | O27: =IF(J27+M27>I27+L27,(J27+M27)-(I27+L27),0) -> 0 | P27: =SUMIF(GL!$D$6488:$D$6532,B27,GL!$H$6488:$H$6532) -> 0 | Q27: =SUMIF(GL!$D$6408:$D$6452,B27,GL!$I$6408:$I$6452) -> 0 | R27: =P27+N27 -> 80934978 | S27: =Q27+O27 -> 0 | X27: =IF(R27>S27,R27-S27,0) -> 80934978 | Y27: =IF(S27>R27,S27-R27,0) -> 0
B28: 1-1203 | C28: Cash Advance | E28: =SUMIF(GL!$D$6:$D$6487,B28,GL!$H$6:$H$6487) -> 29312140 | F28: =SUMIF(GL!$D$6:$D$6487,B28,GL!$I$6:$I$6487) -> 41929151 | I28: =IF(E28>F28,E28-F28,0) -> 0 | J28: =IF(F28>E28,F28-E28,0) -> 12617011 | L28: 39037464 | N28: =IF(I28+L28>J28+M28,(I28+L28)-(J28+M28),0) -> 26420453 | O28: =IF(J28+M28>I28+L28,(J28+M28)-(I28+L28),0) -> 0 | P28: =SUMIF(GL!$D$6488:$D$6532,B28,GL!$H$6488:$H$6532) -> 0 | Q28: =SUMIF(GL!$D$6408:$D$6452,B28,GL!$I$6408:$I$6452) -> 0 | R28: =P28+N28 -> 26420453 | S28: =Q28+O28 -> 0 | X28: =IF(R28>S28,R28-S28,0) -> 26420453 | Y28: =IF(S28>R28,S28-R28,0) -> 0
B29: 1-1210 | C29: AR Credit Card | E29: =SUM(E30:E37) -> 1988881010 | F29: =SUM(F30:F37) -> 2116535501 | G29: =SUM(G30:G37) -> 0 | H29: =SUM(H30:H37) -> 0 | I29: =SUM(I30:I37) -> 143750 | J29: =SUM(J30:J37) -> 127798241 | K29: =SUM(K30:K37) -> 0 | L29: =SUM(L30:L37) -> 192358312 | ... Y29: =SUM(Y30:Y37) -> 0
B30: 1-1211 | C30: GOPAY | E30: =SUMIF(GL!$D$6:$D$6487,B30,GL!$H$6:$H$6487) -> 222000 | F30: =SUMIF(GL!$D$6:$D$6487,B30,GL!$I$6:$I$6487) -> 222000 | I30: =IF(E30>F30,E30-F30,0) -> 0 | J30: =IF(F30>E30,F30-E30,0) -> 0 | N30: =IF(I30+L30>J30+M30,(I30+L30)-(J30+M30),0) -> 0 | O30: =IF(J30+M30>I30+L30,(J30+M30)-(I30+L30),0) -> 0 | P30: =SUMIF(GL!$D$6488:$D$6532,B30,GL!$H$6488:$H$6532) -> 0 | Q30: =SUMIF(GL!$D$6408:$D$6452,B30,GL!$I$6408:$I$6452) -> 0 | R30: =P30+N30 -> 0 | S30: =Q30+O30 -> 0 | X30: =IF(R30>S30,R30-S30,0) -> 0 | Y30: =IF(S30>R30,S30-R30,0) -> 0
B31: 1-1212 | C31: Mega Card | E31: =SUMIF(GL!$D$6:$D$6487,B31,GL!$H$6:$H$6487) -> 0 | F31: =SUMIF(GL!$D$6:$D$6487,B31,GL!$I$6:$I$6487) -> 0 | I31: =IF(E31>F31,E31-F31,0) -> 0 | J31: =IF(F31>E31,F31-E31,0) -> 0 | N31: =IF(I31+L31>J31+M31,(I31+L31)-(J31+M31),0) -> 0 | O31: =IF(J31+M31>I31+L31,(J31+M31)-(I31+L31),0) -> 0 | P31: =SUMIF(GL!$D$6488:$D$6532,B31,GL!$H$6488:$H$6532) -> 0 | Q31: =SUMIF(GL!$D$6408:$D$6452,B31,GL!$I$6408:$I$6452) -> 0 | R31: =P31+N31 -> 0 | S31: =Q31+O31 -> 0 | X31: =IF(R31>S31,R31-S31,0) -> 0 | Y31: =IF(S31>R31,S31-R31,0) -> 0
B32: 1-1213 | C32: Mandiri Card TBB | E32: =SUMIF(GL!$D$6:$D$6487,B32,GL!$H$6:$H$6487) -> 1543583788 | F32: =SUMIF(GL!$D$6:$D$6487,B32,GL!$I$6:$I$6487) -> 1608132299 | I32: =IF(E32>F32,E32-F32,0) -> 0 | J32: =IF(F32>E32,F32-E32,0) -> 64548511 | L32: 122329062 | N32: =IF(I32+L32>J32+M32,(I32+L32)-(J32+M32),0) -> 57780551 | O32: =IF(J32+M32>I32+L32,(J32+M32)-(I32+L32),0) -> 0 | P32: =SUMIF(GL!$D$6488:$D$6532,B32,GL!$H$6488:$H$6532) -> 0 | Q32: =SUMIF(GL!$D$6408:$D$6452,B32,GL!$I$6408:$I$6452) -> 0 | R32: =P32+N32 -> 57780551 | S32: =Q32+O32 -> 0 | X32: =IF(R32>S32,R32-S32,0) -> 57780551 | Y32: =IF(S32>R32,S32-R32,0) -> 0 | Z32: V | AA32: 57780551 | AB32: =X32-AA32 -> 0
B33: 1-1214 | C33: BRI CARD CC | E33: =SUMIF(GL!$D$6:$D$6487,B33,GL!$H$6:$H$6487) -> 5877351 | F33: =SUMIF(GL!$D$6:$D$6487,B33,GL!$I$6:$I$6487) -> 5877351 | I33: =IF(E33>F33,E33-F33,0) -> 0 | J33: =IF(F33>E33,F33-E33,0) -> 0 | N33: =IF(I33+L33>J33+M33,(I33+L33)-(J33+M33),0) -> 0 | O33: =IF(J33+M33>I33+L33,(J33+M33)-(I33+L33),0) -> 0 | P33: =SUMIF(GL!$D$6488:$D$6532,B33,GL!$H$6488:$H$6532) -> 0 | Q33: =SUMIF(GL!$D$6408:$D$6452,B33,GL!$I$6408:$I$6452) -> 0 | R33: =P33+N33 -> 0 | S33: =Q33+O33 -> 0 | X33: =IF(R33>S33,R33-S33,0) -> 0 | Y33: =IF(S33>R33,S33-R33,0) -> 0
B34: 1-1215 | C34: GRAB / OVO | E34: =SUMIF(GL!$D$6:$D$6487,B34,GL!$H$6:$H$6487) -> 4617625 | F34: =SUMIF(GL!$D$6:$D$6487,B34,GL!$I$6:$I$6487) -> 4473875 | I34: =IF(E34>F34,E34-F34,0) -> 143750 | J34: =IF(F34>E34,F34-E34,0) -> 0 | N34: =IF(I34+L34>J34+M34,(I34+L34)-(J34+M34),0) -> 143750 | O34: =IF(J34+M34>I34+L34,(J34+M34)-(I34+L34),0) -> 0 | P34: =SUMIF(GL!$D$6488:$D$6532,B34,GL!$H$6488:$H$6532) -> 0 | Q34: =SUMIF(GL!$D$6408:$D$6452,B34,GL!$I$6408:$I$6452) -> 0 | R34: =P34+N34 -> 143750 | S34: =Q34+O34 -> 0 | X34: =IF(R34>S34,R34-S34,0) -> 143750 | Y34: =IF(S34>R34,S34-R34,0) -> 0 | Z34: V | AA34: 143750 | AB34: =X34-AA34 -> 0
B35: 1-1216 | C35: Credit Card Cimb Niaga TBB | E35: =SUMIF(GL!$D$6:$D$6487,B35,GL!$H$6:$H$6487) -> 80612915 | F35: =SUMIF(GL!$D$6:$D$6487,B35,GL!$I$6:$I$6487) -> 103334000 | I35: =IF(E35>F35,E35-F35,0) -> 0 | J35: =IF(F35>E35,F35-E35,0) -> 22721085 | L35: 22721085 | N35: =IF(I35+L35>J35+M35,(I35+L35)-(J35+M35),0) -> 0 | O35: =IF(J35+M35>I35+L35,(J35+M35)-(I35+L35),0) -> 0 | P35: =SUMIF(GL!$D$6488:$D$6532,B35,GL!$H$6488:$H$6532) -> 0 | Q35: =SUMIF(GL!$D$6408:$D$6452,B35,GL!$I$6408:$I$6452) -> 0 | R35: =P35+N35 -> 0 | S35: =Q35+O35 -> 0 | X35: =IF(R35>S35,R35-S35,0) -> 0 | Y35: =IF(S35>R35,S35-R35,0) -> 0
B36: 1-1217 | C36: BCA Card TBB | E36: =SUMIF(GL!$D$6:$D$6487,B36,GL!$H$6:$H$6487) -> 353967331 | F36: =SUMIF(GL!$D$6:$D$6487,B36,GL!$I$6:$I$6487) -> 394495976 | I36: =IF(E36>F36,E36-F36,0) -> 0 | J36: =IF(F36>E36,F36-E36,0) -> 40528645 | L36: 47308165 | N36: =IF(I36+L36>J36+M36,(I36+L36)-(J36+M36),0) -> 6779520 | O36: =IF(J36+M36>I36+L36,(J36+M36)-(I36+L36),0) -> 0 | P36: =SUMIF(GL!$D$6488:$D$6532,B36,GL!$H$6488:$H$6532) -> 0 | Q36: =SUMIF(GL!$D$6408:$D$6452,B36,GL!$I$6408:$I$6452) -> 0 | R36: =P36+N36 -> 6779520 | S36: =Q36+O36 -> 0 | X36: =IF(R36>S36,R36-S36,0) -> 6779520 | Y36: =IF(S36>R36,S36-R36,0) -> 0 | Z36: V | AA36: 6779520 | AB36: =X36-AA36 -> 0
B37: 1-1218 | C37: STARXP | E37: =SUMIF(GL!$D$6:$D$6487,B37,GL!$H$6:$H$6487) -> 0 | F37: =SUMIF(GL!$D$6:$D$6487,B37,GL!$I$6:$I$6487) -> 0 | I37: =IF(E37>F37,E37-F37,0) -> 0 | J37: =IF(F37>E37,F37-E37,0) -> 0 | N37: =IF(I37+L37>J37+M37,(I37+L37)-(J37+M37),0) -> 0 | O37: =IF(J37+M37>I37+L37,(J37+M37)-(I37+L37),0) -> 0 | P37: =SUMIF(GL!$D$6488:$D$6532,B37,GL!$H$6488:$H$6532) -> 0 | Q37: =SUMIF(GL!$D$6408:$D$6452,B37,GL!$I$6408:$I$6452) -> 0 | R37: =P37+N37 -> 0 | S37: =Q37+O37 -> 0 | X37: =IF(R37>S37,R37-S37,0) -> 0 | Y37: =IF(S37>R37,S37-R37,0) -> 0
B39: 1-1220 | C39: Related Party | E39: =SUM(E40) -> 39325785 | F39: =SUM(F40) -> 25770573 | G39: =SUM(G40) -> 0 | H39: =SUM(H40) -> 0 | I39: =SUM(I40) -> 13555212 | J39: =SUM(J40) -> 0 | K39: =SUM(K40) -> 0 | L39: =SUM(L40) -> 18738149444 | ... Y39: =SUM(Y40) -> 0
B40: 1-1221 | C40: Intercompany Receivable – Treasury StarPOINTS | E40: =SUMIF(GL!$D$6:$D$6487,B40,GL!$H$6:$H$6487) -> 39325785 | F40: =SUMIF(GL!$D$6:$D$6487,B40,GL!$I$6:$I$6487) -> 25770573 | I40: =IF(E40>F40,E40-F40,0) -> 13555212 | J40: =IF(F40>E40,F40-E40,0) -> 0 | L40: 18738149444 | N40: =IF(I40+L40>J40+M40,(I40+L40)-(J40+M40),0) -> 18751704656 | O40: =IF(J40+M40>I40+L40,(J40+M40)-(I40+L40),0) -> 0 | P40: =SUMIF(GL!$D$6488:$D$6532,B40,GL!$H$6488:$H$6532) -> 0 | Q40: =SUMIF(GL!$D$6408:$D$6452,B40,GL!$I$6408:$I$6452) -> 0 | R40: =P40+N40 -> 18751704656 | S40: =Q40+O40 -> 0 | X40: =IF(R40>S40,R40-S40,0) -> 18751704656 | Y40: =IF(S40>R40,S40-R40,0) -> 0
B41: 1-1299 | C41: Total Account Receivables | E41: =E39+E29+E25 -> 2081144958 | F41: =F39+F29+F25 -> 2208192628 | G41: =G39+G29+G25 -> 0 | H41: =H39+H29+H25 -> 0 | I41: =I39+I29+I25 -> 13698962 | J41: =J39+J29+J25 -> 140746632 | K41: =K39+K29+K25 -> 0 | L41: =L39+L29+L25 -> 19050811578 | ... Y41: =Y39+Y29+Y25 -> 0
B43: 1-1300 | C43: INVENTORY
